Workbook

Sheet Deckblatt
C9: Reifegradmodell für die Technische Dokumentation
C26: Erstellt durch: | E26: Christian Koch
C27: Version: | E27: 2.0
C28: Letzte Änderung: | E28: 45994
C29: Credit: | E29: Victor Wolf

Sheet Einführung
B6: Willkommen zum Reifegradmodell für die Technische Dokumentation
B9: Das Reifegradmodell ist ein fragenbasiertes Tool zur Erhebung der Reifegrade der technischen Dokumentation. Es wurde entwickelt, um Unternehmen eine Hilfestellung bei der nachhaltigen Weiterentwicklung der technischen Dokumentation zu geben.
B10: Das Reifegradmodell basiert auf Ergebnissen einer Recherche zu bestehenden Reifegradmodellen sowie der Auswertung von Interviews. Das RGM besteht aus 33 Subdimmensionen, aufgeteilt auf 8 Dimensionen und ist modellhaft zu verstehen. Dies bedeutet, dass die Aspekte der Dimensionen je nach Organisation unterschiedlich interpretiert werden können. Die Nutzenden sind herzlich dazu eingeladen, eigene, unternehmensspezifische Punkte zu ergänzen.
B11: Kontaktdaten für Feedback und Fragen: christian4.koch@tu-dortmund.de
B12: Das Tool deckt die folgenden Bereiche ab. Die jeweiligen Betrachtungsobjekte sind farblich hervorgehoben.
B13: Technische Dokumentation (TD):
B14: Relevante Themenbereiche der technischen Dokumentation.
B16: Organisation (OG):
B17: Relevante Themenbereiche der Organisation, die mit der technischen Dokumentation in Verbindung stehen bzw. diese beeinflussen.

Sheet Dashboard
B6: Dashboard
C10: Name der Organisation: | G10: Datum der Durchführung:
C12: Beispiel GmbH | G12: TT.MM.JJJJ
C14: Bereich:
C16: Bereich A
C18: Erhebung durchgeführt von: | G18: Angestrebtes Ziel:
C20: Herr/Frau Beispiel | G20: Quantitativ gemanagt
B23: Visualisiertes Ergebnis der Reifegraderhebung: | L23: Ergebnis in Tabellenform:
M27: Kürzel | N27: Themenbereich | O27: Reifegrad | P27: Link
M28: {=Data!B3:C35} -> TD1.1 | N28: Prozessinitierung | O28: =Data!D3 -> 0 | P28: Hier klicken
M29: TD1.2 | N29: Informationsbeschaffung | O29: =Data!D4 -> 0 | P29: Hier klicken
M30: TD1.3 | N30: Interne Zusammenarbeit | O30: =Data!D5 -> 0 | P30: Hier klicken
M31: TD1.4 | N31: Externe Zusammenarbeit | O31: =Data!D6 -> 0 | P31: Hier klicken
M32: TD1.5 | N32: Rechtskonformität | O32: =Data!D7 -> 0 | P32: Hier klicken
M33: TD1.6 | N33: Qualitätssicherung | O33: =Data!D8 -> 0 | P33: Hier klicken
M34: TD2.1 | N34: Dokumentationsstrukturierung | O34: =Data!D9 -> 0 | P34: Hier klicken
M35: TD2.2 | N35: Variantenmanagement | O35: =Data!D10 -> 0 | P35: Hier klicken
M36: TD2.3 | N36: Metadatenmanagement | O36: =Data!D11 -> 0 | P36: Hier klicken
M37: TD2.4 | N37: Terminologiemanagement | O37: =Data!D12 -> 0 | P37: Hier klicken
M38: TD2.5 | N38: Übersetzungsmanagement | O38: =Data!D13 -> 0 | P38: Hier klicken
M39: TD2.6 | N39: Aktualität | O39: =Data!D14 -> 0 | P39: Hier klicken
M40: TD2.7 | N40: Versionierung | O40: =Data!D15 -> 0 | P40: Hier klicken
... M60: OG4.4 | N60: Produktions-IT-Infrastruktur | O60: =Data!D35 -> 0 | P60: Hier klicken
M63: Legende:
M64: 1 - initial
M65: 2 - Gemanagt
M66: 3 - Definiert
M67: 4 - Quantitativ gemanagt
M68: 5 - Optimiert

Sheet Ausfüllhinweise
B6: Ausfüllhinweise zum Reifegradmodell
B9: Anhand des Reifegradmodells ist eine rasche und einheitliche Bestimmung von Reifegraden der technischen Dokumentation möglich. Hierzu werden je Subdimension spezifische Fragestellungen beantwortet. Das Reifegradmodell orientiert sich an den Reifegradstufen der Capability Maturity Model Integration (CMMI).
B11: Beschreibung der Reifegradstufen:
C13: Reifegradstufe | D13: Beschreibung
C14: 1 - initial | D14: Prozesse bleiben unvorhersehbar und reaktiv. Der Erfolg auf dieser Ebene hängt hauptsächlich von den individuellen Anstrengungen und nicht von etablierten organisatorischen Prozessen ab.
C15: 2 - gemanagt | D15: Organisationen auf dieser Ebene etablieren grundlegende Projektmanagementpraktiken. Projekte folgen grundlegenden Planungs- und Kontrollmechanismen und führen so zu vorhersehbareren Ergebnissen.
C16: 3 - definiert | D16: Diese Ebene markiert einen deutlichen Wandel hin zu einer unternehmensweiten Prozessstandardisierung. Auf dieser Ebene werden einheitliche Vorgehensweisen in der gesamten Organisation etabliert und die Variabilität bei der Projektausführung verringert.
C17: 4 - quantitativ gemanagt | D17: Organisationen erreichen eine präzise Prozesskontrolle. Projekte arbeiten mit einem hohen Maß an Vorhersehbarkeit und nutzen Kennzahlen zur Verwaltung der Prozess- und Produktqualität.
C18: 5 - optimiert | D18: Organisationen auf dieser Ebene verbessern ihre Prozesse systematisch durch inkrementelle und innovative Änderungen.
B20: Um eine inhaltliche Abgrenzung zwischen den jeweiligen Reifegradstufen zu ermöglichen, werden Schlüsselwörter verwendet. Diese werden nachfolgend erläutert.
B22: Beschreibung der Schlüsselwörter:
C24: Schlüsselwort | D24: Interpretation/Bedeutung
C25: Situativ/Ad-Hoc | D25: Der Prozess wird anlassbezogen durchgeführt und beispielsweise durch externe Trigger angestoßen.
C26: Gelegentlich | D26: Der Prozess wird zwar wiederholt durchgeführt, jedoch ohne fest definiertes Intervall.
C27: Regelmäßig | D27: Der Prozess wird in einem fest definierten Intervall durchgeführt.
C28: Regelmäßig überprüft | D28: Die Einhaltung der fest definierten Intervalle wird mit Hilfe von Kennzahlen gesteuert.
C29: Kontinuierlich verbessert | D29: Der Prozess wird durch die durchführenden Mitarbeiter kontinuierlich verbessert.
B31: Zur Identifikation der Reifegrade werden spezifische Fragestellungen definiert. Die Antwortmöglichkeiten spiegeln den Umsetzungsgrad des jeweiligen Prüfkriterium wieder. Basierend auf der Konsolidierung der Antworten wird der Reifegrad des betrachteten Prozessbereich identifiziert. Das methodische Basismodell zur Identifikation der Reifegrade ist die Normreihe ISO/IEC 330xx.
B33: Beschreibung der Antwortmöglichkeiten
C35: Antwort | D35: Umsetzungsgrad | E35: Beschreibung
C36: Nicht anwendbar | D36: / | E36: Das Prüfkriterium ist nicht auf die Organisation anwendbar. Sollten alle Fragen einer Stufe nicht anwendbar sein, verbleibt der Reifegradauf der darunter liegenden Stufe bzw. als #NV.
C37: Gar nicht | D37: 0% - 15% | E37: Es gibt keinen Nachweis für die Erreichung des Prüfkriteriums.
C38: In ein Paar Fällen | D38: >15% - 50% | E38: Es bestehen teilweise Anzeichen für die Erreichung des Prüfkriteriums.
C39: In den meisten Fällen | D39: >50% - 85% | E39: Es gibt signifikante Anzeichen für die Erreichung des Prüfkriteriums.
C40: Vollständig | D40: >85% - 100% | E40: Es gibt einen vollständigen Nachweis für die Erreichung des Prüfkriteriums.
C42: WICHTIG!
C43: Bitte beachten Sie:
C44: Die Fragen des Reifegradmodells sind so formuliert, dass jede Reifegradstufe auf den vorhergehenden Stufen aufbaut. Das bedeutet: Wenn Ihre Organisation eine höhere Stufe bereits erreicht hat und der beschriebene Zustand einer niedrigeren Stufe dadurch überwunden wurde (z. B. Varianten werden nicht mehr manuell gepflegt), ist die Frage dennoch mit „Vollständig“ zu beantworten. „Vollständig“ bedeutet in diesem Zusammenhang: Der beschriebene Zustand dieser Stufe wurde vollständig erreicht oder übertroffen. Antworten wie „Gar nicht“, „In ein paar Fällen“ oder „In den meisten Fällen“ würden fälschlicherweise anzeigen, dass diese Stufe noch nicht erfüllt ist.

Sheet Erläuterung
B6: Erläuterung der Erhebungsblätter
C10: Überblick der Tabellenblätter:
C12: Jeder Untersuchungsgegenstand hat ein eigenes Erhebungsblatt. Die Erhebungsblätter sind nicht voneinander abhängig und können auch einzeln bearbeitet werden. Die Erhebungsblätter sind je nach Art kategorisiert: Blau: Technische Dokumentation (TD) Orange: Organisation (OG)
C15: Wichtig: Diese Reifegraderhebung zielt auf die Inhalte technischer Dokumentation ab. Sowohl das Referenzmodell als auch die einzelnen Prozesse sind schematisch zu verstehen und dienen als inhaltliche Stütze. Sie müssen weder nach diesem Schema etabliert, noch nach dieser Vorgehensweise umgesetzt werden!
C16: Ablauf der Erhebung:
C18: Zur Identifikation der Reifegrade werden spezifische Fragestellungen je Reifegrad gestellt. [1] Diese Fragen sind mit den vordefinierten Antwortmöglichkeiten zu beantworten. [2] Für jede Stufe wird der konkrete Nutzen für die Organisation dargestellt. [3] Zusätzlich besteht die Möglichkeit, einen Kommentar im Freitextfeld zu hinterlassen. [4]
C37: Weitere Informationen anzeigen lassen:
C39: [5] Durch Klicken des [+] Symbols können Sie sich zusätzliche Informationen zu den Prüffragen anzeigen lassen.
C40: [6] Durch Klicken des [+] Symbols können Sie sich den jeweiligen schematischen Prozess-Steckbrief anzeigen lassen.
C42: Wie die Reifegrade berechnet werden:
C44: Der Reifegrad für jeden Prozess wird auf der Grundlage der gegebenen Antwort berechnet und in der Bewertungs-Zelle angezeigt. [7] Die Reifegrad-Skala ist kumulativ. Die Reifegradbewertung beginnt für jeden Prozess bei 0 und arbeitet aufwärts. Jede Reifegradstufe baut auf den vorherigen Stufen auf. Damit die nächsthöhere Reifegradstufe erreicht werden kann, wird die vollständige Umsetzung der vorherigen Stufen benötigt. Das bedeutet auch, dass die Umsetzung teilweise kontra-intuitiv ausgewählt werden muss. Die Festlegung der Reifegradstufen erfolgt anhand von Abnahmekriterien. Diese sind jeder Reifegradstufe zugeordnet und beschreiben die benötigten Fähigkeiten je Reifegradstufe. Die Abnahmekriterien können unter [5] angezeigt werden.

Sheet Glossar
B6: Glossar
C10: Begriffe, die unterstrichen und in grüner Farbe dargestellt sind, sind in diesem Glossar zu finden. Mit einem Klick auf die Zelle, in der der Begriff steht, gelangt man zum Glossar.
C13: A
C14: API (Application Programmable Interface) | E14: Programmteil, der von einem Softwaresystem anderen Programmen zur Anbindung an das System zur Verfügung gestellt wird (https://de.wikipedia.org/wiki/Programmierschnittstelle)
C15: C
C16: CCMS (Component Content Management System) | E16: spezialisierte Form eines Content Management Systems (CMS), die speziell für die Verwaltung, Speicherung und Wiederverwendung von Inhalten in einer granularen Form, bekannt als Komponenten, entwickelt wurde (https://carstens-techdok.de/ccms/)
C17: CMS (Content Management System) | E17: Software oder Service zur gemeinschaftlichen Erstellung, Bearbeitung, Organisation, Darstellung und Auslieferung digitaler Inhalte (Content) zur Verwendung in Webseiten, Apps, Digital Signage und anderen Medienformen (https://de.wikipedia.org/wiki/Content-Management-System)
C18: Corporate Design | E18: Teil des Corporate Branding. Es umfasst die visuelle und sprachliche Inszenierung der Marke und dient dazu, die Identität und Werte eines Unternehmens sichtbar zu machen (https://www.syndicate.de/was-ist-corporate-design/#:~:text=Das%20Corporate%20Design%20ist%20neben,eines%20Unternehmens%20sichtbar%20zu%20machen.)
C19: Corporate Identity | E19: Gesamtheit der Merkmale, die ein Unternehmen kennzeichnet und es von anderen Unternehmen unterscheidet. Die Corporate Identity ist damit das Selbstbild des Unternehmens (https://de.wikipedia.org/wiki/Corporate_Identity)
C20: CSR (Corporate Social Responsibility) | E20: Integration von ökologischen, sozialen und wirtschaftlichen Faktoren in die Unternehmenstätigkeit auf freiwilliger und manchmal auch rechtlicher Basis. Die Aktivitäten der Unternehmen werden hier im weitesten Sinne verstanden: wirtschaftliche Aktivitäten, interne Interaktionen (Arbeitnehmer, Manager, Aktionäre) und externe Interaktionen (Lieferanten, Kunden) (https://de.wikipedia.org/wiki/Corporate_Social_Responsibility)
C21: D
C22: DMS (Document Management System) | E22: datenbankgestützte Verwaltung elektronischer Dokumente (https://de.wikipedia.org/wiki/Dokumentenmanagement)
C23: DITA (Darwin Information Typing Architecture) | E23: Dokumentenformat, ähnlich dem bekannten DocBook. DITA wird vom OASIS DITA Technical Committee als freie Architektur entwickelt und steht als Dokumenttypdefinition (DTD) kostenlos zur Verfügung. Das Format basiert auf XML: Im Gegensatz zu DocBook gibt es für DITA keine SGML-basierte Dokumenttypdefinition (DTD) (https://de.wikipedia.org/wiki/Darwin_Information_Typing_Architecture)
C24: E
C25: ECLASS | E25: Datenstandard für die Klassifizierung von Produkten und Dienstleistungen mit Hilfe von standardisierten ISO-konformen Merkmalen. Der ECLASS-Standard ermöglicht den digitalen Austausch von Produktstammdaten über Branchen, Länder, Sprachen oder Organisationen hinweg (https://de.wikipedia.org/wiki/ECLASS)
C26: ERP (Enterprise Resource Planning) | E26: unternehmerische Aufgabe, Personal, Ressourcen, Kapital, Betriebsmittel, Material sowie Informations- und Kommunikationstechnik im Sinne des Unternehmenszwecks rechtzeitig und bedarfsgerecht zu planen, zu steuern und zu verwalten. Gewährleistet werden soll ein effizienter betrieblicher Wertschöpfungsprozess und eine stetig optimierte Steuerung der unternehmerischen und betrieblichen Abläufe (https://de.wikipedia.org/wiki/Enterprise-Resource-Planning)
C27: Ethernet | E27: Technik, die Software (Protokolle usw.) und Hardware (Kabel, Verteiler, Netzwerkkarten usw.) für kabelgebundene Datennetze spezifiziert, welche ursprünglich für lokale Datennetze (LANs) gedacht war und daher auch als LAN-Technik bezeichnet wird. Sie ermöglicht den Datenaustausch in Form von Datenframes zwischen den in einem lokalen Netz (LAN) angeschlossenen Geräten (https://de.wikipedia.org/wiki/Ethernet)
C28: F
C29: Feldbus | E29: Bussystem, das in einer Anlage Feldgeräte wie Messfühler (Sensoren) und Stellglieder (Aktoren) zur Kommunikation mit einem Automatisierungsgerät verbindet. Wenn mehrere Kommunikationsteilnehmer ihre Nachrichten über dieselbe Leitung senden, dann muss festgelegt sein, wer (Kennung) was (Messwert, Befehl) wann (Initiative) sagt. Hierfür gibt es normierte Protokolle (https://de.wikipedia.org/wiki/Feldbus)
C30: H
C31: Headless Delivery | E31: bezieht sich auf eine Architektur, die das Content-Backend von der Frontend-Anzeige entkoppelt, sodass Inhalte über eine API an beliebige Kanäle und Endgeräte verteilt werden können. Im Gegensatz zu herkömmlichen Systemen wird bei Headless Delivery nur der reine Inhalt (oft als Daten wie JSON) an die Benutzeroberfläche ausgeliefert, was eine größere Flexibilität und Skalierbarkeit bei der Personalisierung von Inhalten über verschiedene Kanäle hinweg ermöglicht (https://documentation.coremedia.com/discover/api/headless-server-api/)
C32: I
C33: iiRDS (intelligent information Request and Delivery Standard) | E33: technischer Standard für die Auslieferung von digitalen Anwenderinformationen, z. B. elektronischen Betriebsanleitungen und Gebrauchsanleitungen (https://de.wikipedia.org/wiki/IiRDS)
C34: M
C35: Middleware | E35: anwendungsneutrale Programme, die so zwischen Anwendungen vermitteln, dass die Komplexität dieser Applikationen und ihre Infrastruktur verborgen werden (https://de.wikipedia.org/wiki/Middleware)
C36: Modell, semantisches | E36: im Rahmen der Datenmodellierung eine abstrakte, formale Beschreibung und Darstellung eines Ausschnittes der in einem bestimmten Zusammenhang (z. B. eines Projekts) „wahrgenommenen Welt“. Zur Formulierung semantischer Datenmodelle existieren verschiedene Modellierungssprachen, von denen das Entity-Relationship-Modell das bekannteste ist (https://de.wikipedia.org/wiki/Semantisches_Datenmodell)
C37: O
C38: Omnichannel | E38: kanalübergreifendes Geschäftsmodell für Unternehmen zum Verbessern des Kundenerfahrungsmanagements. Der Ansatz wird in den Bereichen Gesundheitswesen, Regierungsbehörden und Finanzdienstleistungen sowie in der Einzelhandels[1]- und Telekommunikationsbranche genutzt, wobei als Kanäle z. B. physische Standorte, FAQ-Webseiten, soziale Medien, Live-Webchats, mobile Anwendungen und Telefonkommunikation zum Einsatz kommen.[2][3] Unternehmen, die das Omnichannel-Konzept umsetzen, argumentieren, dass Kunden über mehrere Kanäle gleichzeitig in ständigem Kontakt mit einem Unternehmen sein möchten (https://de.wikipedia.org/wiki/Omnichannel)
C39: Ontologie | E39: sprachlich gefasste und formal geordnete Darstellungen einer Menge von Begriffen und der zwischen ihnen bestehenden Beziehungen in einem bestimmten Gegenstandsbereich (in Anlehnung an den klassischen Begriff der Ontologie). Sie werden dazu genutzt, „Wissen“ in digitalisierter und formaler Form zwischen Prozessen (oft Anwendungsprogrammen) und Diensten auszutauschen. Wissen umfasst dabei sowohl Allgemeinwissen als auch Wissen über sehr spezielle Themengebiete und Vorgänge (https://de.wikipedia.org/wiki/Ontologie_(Informatik))
C40: OPC UA | E40: Standard für den Datenaustausch als plattformunabhängige, service-orientierte Architektur (SOA)[1]. Sie führt die Fähigkeit ein, Maschinendaten (Regelgrößen, Messwerte, Parameter usw.) nicht nur zu transportieren, sondern auch maschinenlesbar semantisch zu beschreiben (https://de.wikipedia.org/wiki/OPC_Unified_Architecture)
C41: P
C42: PDM (Product Data Management) | E42: speichert und verwaltet produktdefinierende, repräsentierende und präsentierende Daten als Ergebnis der Produktentwicklung und stellt sie in nachgelagerten Phasen des Produktlebenszyklus zur Verfügung (https://de.wikipedia.org/wiki/Produktdatenmanagement)
C43: PIM (Product Information Management) | E43: Bereitstellung von Produktinformationen für den Einsatz in verschiedenen Ausgabemedien beziehungsweise Vertriebskanälen sowie für unterschiedliche Standorte (https://de.wikipedia.org/wiki/Produktinformationsmanagement)
C44: PLM (Product Lifecycle Management) | E44: Konzept zur nahtlosen Integration sämtlicher Informationen, die im Verlauf des Lebenszyklus eines Produktes anfallen (https://de.wikipedia.org/wiki/Product-Lifecycle-Management)
C45: T
C46: Team, crossfunktionales | E46: Gruppen von Menschen mit einer Vielzahl von Fähigkeiten und Erfahrungen, die alle auf ein gemeinsames Ziel hinarbeiten. Statt also ein Projekt von Team zu Team bis zum Markteinführungstermin weiterzugeben, kann ein einziges Team jeden Aspekt des Projekts bearbeiten (https://www.dropbox.com/de/resources/cross-functional-teams)
C47: Terminologiemapping | E47: Zuordnung von Begriffen aus unterschiedlichen Terminologien, um deren Bedeutungen abzugleichen oder zu harmonisieren.
C48: Translation Memory | E48: Datenbank mit strukturierten Übersetzungen, die die Hauptkomponente von Anwendungen zur rechnerunterstützten Übersetzung (Computer-aided translation, abgekürzt CAT) darstellt (https://de.wikipedia.org/wiki/%C3%9Cbersetzungsspeicher)
C49: U
C50: URI (Uniform Resource Identifier) | E50: Identifikator bestehend aus einer Zeichenfolge, die zur Identifizierung einer abstrakten oder physischen Ressource dient. URIs werden zur Bezeichnung von Ressourcen (wie Webseiten, sonstigen Dateien, Aufruf von Webservices, aber auch E-Mail-Empfängern) im Internet und dort vor allem im WWW eingesetzt (https://de.wikipedia.org/wiki/Uniform_Resource_Identifier)

Sheet Offene Punkte
B4: {=INDEX(_xlfn._xlws.FILTER('TD1.1'!B16:H32,'TD1.1'!H16:H32<>"Vollständig"),,1)} -> 1 | C4: =IF(B4=0,C3,B4) -> 1 | D4: {=INDEX(_xlfn._xlws.FILTER('TD1.1'!B16:H32,'TD1.1'!H16:H32<>"Vollständig"),,2)} -> Ist sichergestellt, dass die Mitarbeitenden wissen – basierend auf ihrer Erfahrung oder etablierten Kenntnissen –, wann sie im Entwicklungsprozess mit dem Redaktionsprozess beginnen müssen?
B5: 2 | C5: =IF(B5=0,C4,B5) -> 2 | D5: Sind in Entwicklungsprozessen allgemeine erforderliche Ressourcen für den Redaktionsprozess vorab bekannt? Sind ausreichend Ressourcen vorhanden?
B6: 0 | C6: =IF(B6=0,C5,B6) -> 2 | D6: Sind in Entwicklungsprozessen Deadlines für die Fertigstellung der Dokumentation definiert? Lässt sich ein Einstiegspunkt für den redaktionellen Prozess bestimmen?
B7: 0 | C7: =IF(B7=0,C6,B7) -> 2 | D7: Ist die Vorgehensweise zur Etablierung eines auf den Entwicklungsprozess angeglichenen Redaktionsprozess geplant (Beispielsweise in einer Roadmap)?
B8: 0 | C8: =IF(B8=0,C7,B8) -> 2 | D8: Existiert eine Leitlinie für durchzuführende Aufgaben im Redaktionsprozess und wird diese gelegentlich aktualisiert?
B9: 3 | C9: =IF(B9=0,C8,B9) -> 3 | D9: Wurde der Redaktionsprozess in Arbeitspakete zerlegt und sind diese an einzelne Entwicklungsaufgaben gekoppelt?
B10: 0 | C10: =IF(B10=0,C9,B10) -> 3 | D10: Finden regelmäßige Abstimmungen mit allen relevanten Stakeholdern statt?
B11: 0 | C11: =IF(B11=0,C10,B11) -> 3 | D11: Wurde eine Ressourcenplanung für einzelne Aufgaben im Redaktionsprozess durchgeführt?
B12: 0 | C12: =IF(B12=0,C11,B12) -> 3 | D12: Wird der reale Ressourcenbedarf dokumentiert und regelmäßig mit den Planungsdaten verglichen?
B13: 0 | C13: =IF(B13=0,C12,B13) -> 3 | D13: Sind zeitkritische Redaktionsaufgaben bekannt und werden mit entsprechendem Puffer berücksichtigt?
B14: 0 | C14: =IF(B14=0,C13,B14) -> 3 | D14: Werden Verbesserungspotentiale zur Vorgehensweise im Redaktionsprozess identifiziert?
B15: 4 | C15: =IF(B15=0,C14,B15) -> 4 | D15: Ist die Ressourcenplanung systemgestützt an den Entwicklungsprozess gekoppelt?
B16: 0 | C16: =IF(B16=0,C15,B16) -> 4 | D16: Werden die Performance-Daten aus dem Redaktionsprozess weiter verwendet (z.B. zur verbesserten Prognose des Ressourcenbedarfs)?
... B20: 0 | C20: =IF(B20=0,C19,B20) -> 5 | D20: Werden basierend auf aktuellen Entwicklungen Verbesserungspotentiale für den Redaktionsprozess identifiziert, bewertet und umgesetzt?

Sheet TD1.1
B4: Die Reifegrade werden anhand der jeweiligen Antwort ermittelt. Eine Erläuterung des Aufbaus der Reifegrade und der Antwortmöglichkeiten finden Sie in den Ausfüllhinweisen.
B6: TD1.1 | C6: Redaktionsprozess - Prozessinitiierung | K6: Reifegrad: | L6: =ROUNDDOWN(Z16/0.25,0)*0.25 -> 0 | M6: =IF(L6<1,"Unvollständig",IF(L6<2,"Initial",IF(L6<3,"Gemanagt",IF(L6<4,"Definiert",IF(L6<5,"Quantitativ gemanagt",IF(L6<6,"Optimiert","Ausstehend")))))) -> Unvollständig
B7: Zweck | C7: Startpunkt der redaktionellen Tätigkeiten eindeutig definieren, die erforderlichen Aktivitäten anstoßen und die notwendigen Rahmenbedingungen (z. B. Zuständigkeiten, Ressourcen, Zeitplan) festzulegen, um einen reibungslosen Ablauf der Dokumentationserstellung sicherzustellen.
B8: Ergebnisse | C8: • Ressourcenplanung und Prozessinitiierung sind festgelegt • Zeitplan und Meilensteinplan liegen vor • Redaktionsprozess ist an den Entwicklungsprozess gekoppelt
B9: Basispraktiken | C9: • Erkennen und dokumentieren des Auslösers für den Redaktionsprozess • Sicherstellen, dass alle erforderlichen Ressourcen vorliegen • Verknüpfen der Aktivitäten des Redaktionsprozesses mit Aktivitäten des Entwicklungsprozesses
B10: Arbeitsprodukte | C10: • Startdokumentation • Projektzeitplan • Ressourcenplanung
B12: Erhebung der Reifegrade:
B14: Zu Reifegrad | C14: Kontrollfrage | F14: Abnahmekriterien | H14: Umsetzung | J14: Nutzen bei Erreichen der Stufe | N14: Kommentar/Hinweis | T14: Listenindex | Y14: Zw. Ergebnis | Z14: Ergebnis
B16: 1 | C16: Ist sichergestellt, dass die Mitarbeitenden wissen – basierend auf ihrer Erfahrung oder etablierten Kenntnissen –, wann sie im Entwicklungsprozess mit dem Redaktionsprozess beginnen müssen? | F16: • Mitarbeiter besitzen das Erfahrungswissen zur selbstständigen Initiierung des Redaktionsprozesses | H16: Bitte auswählen | J16: / | S16: =IF(H16="Nicht anwendbar","n.a.",0) -> 0 | T16: =IF(H16="Vollständig",1,0) -> 0 | U16: =IF(H16="In den meisten Fällen",0.75,0) -> 0 | V16: =IF(H16="In ein Paar Fällen",0.5,0) -> 0 | W16: =IF(H16="Gar nicht",0,0) -> 0 | X16: =IF(S16>0,"n.a.",SUM(S16:W16)) -> 0 | Y16: =X16 -> 0 | Z16: =IF(Y16<>"n.a.",SUM(Y16,Y17,Y21,Y27,Y30),NA()) -> 0 | AG16: =IF(X16>0.5,"Umgesetzt","Nicht umgesetzt") -> Nicht umgesetzt
B17: 2 | C17: Sind in Entwicklungsprozessen allgemeine erforderliche Ressourcen für den Redaktionsprozess vorab bekannt? Sind ausreichend Ressourcen vorhanden? | F17: • Die erforderlichen Ressourcen für den Redaktionsprozess sind insgesamt grob bekannt (z.B. Anzahl Personenmonate) • Die Mitarbeitenden verfügen über ausreichend Ressourcen zur Durchführung der Redaktionsarbeit • Deadlines für die Fertigstellung der Dokumentation sind festgelegt und werden größtenteils eingehalten • Die Angleichung des Redaktionsprozesses an den Entwicklungsprozess ist geplant • Es existieren Leitlinien für die Aufgaben im Redaktionsprozess | H17: Bitte auswählen | J17: • Frühere Planbarkeit, da erste Kriterien für den Start vorhanden sind • Vermeidung von kritischen Verzögerungen durch die Redaktion in Einzelfällen • gesteigerte Effizienz durch initale Klärung der Zuständigkeiten --> erste Stabilität | S17: =IF(H17="Nicht anwendbar","n.a.",0) -> 0 | T17: =IF(H17="Vollständig",1,0) -> 0 | U17: =IF(H17="In den meisten Fällen",0.75,0) -> 0 | V17: =IF(H17="In ein Paar Fällen",0.5,0) -> 0 | W17: =IF(H17="Gar nicht",0,0) -> 0 | X17: =IFERROR(SUM(T17:W20)/COUNTIF(H17:H20,"<>Nicht anwendbar"),"n.a.") -> 0 | Y17: =IF(X16=1,X17,0) -> 0 | AG17: =IF(X17>0.5,"Umgesetzt","Nicht umgesetzt") -> Nicht umgesetzt
C18: Sind in Entwicklungsprozessen Deadlines für die Fertigstellung der Dokumentation definiert? Lässt sich ein Einstiegspunkt für den redaktionellen Prozess bestimmen? | H18: Bitte auswählen | S18: =IF(H18="Nicht anwendbar","n.a.",0) -> 0 | T18: =IF(H18="Vollständig",1,0) -> 0 | U18: =IF(H18="In den meisten Fällen",0.75,0) -> 0 | V18: =IF(H18="In ein Paar Fällen",0.5,0) -> 0 | W18: =IF(H18="Gar nicht",0,0) -> 0 | AG18: =IF(X18>0.5,"Umgesetzt","Nicht umgesetzt") -> Nicht umgesetzt
C19: Ist die Vorgehensweise zur Etablierung eines auf den Entwicklungsprozess angeglichenen Redaktionsprozess geplant (Beispielsweise in einer Roadmap)? | H19: Bitte auswählen | S19: =IF(H19="Nicht anwendbar","n.a.",0) -> 0 | T19: =IF(H19="Vollständig",1,0) -> 0 | U19: =IF(H19="In den meisten Fällen",0.75,0) -> 0 | V19: =IF(H19="In ein Paar Fällen",0.5,0) -> 0 | W19: =IF(H19="Gar nicht",0,0) -> 0 | AG19: =IF(X19>0.5,"Umgesetzt","Nicht umgesetzt") -> Nicht umgesetzt
C20: Existiert eine Leitlinie für durchzuführende Aufgaben im Redaktionsprozess und wird diese gelegentlich aktualisiert? | H20: Bitte auswählen | S20: =IF(H20="Nicht anwendbar","n.a.",0) -> 0 | T20: =IF(H20="Vollständig",1,0) -> 0 | U20: =IF(H20="In den meisten Fällen",0.75,0) -> 0 | V20: =IF(H20="In ein Paar Fällen",0.5,0) -> 0 | W20: =IF(H20="Gar nicht",0,0) -> 0 | AG20: =IF(X20>0.5,"Umgesetzt","Nicht umgesetzt") -> Nicht umgesetzt
B21: 3 | C21: Wurde der Redaktionsprozess in Arbeitspakete zerlegt und sind diese an einzelne Entwicklungsaufgaben gekoppelt? | F21: • Der Redaktionsprozess wurde in Einzelarbeitspakete zerlegt • Die Arbeitspakete sind mit Arbeitspaketen im Entwicklungsprozess verknüpft • Die Einzelarbeitspakete unterliegen einer konkreten Ressourcenplanung • Der tatsächliche Ressourcenbedarf wird dokumentiert • Ist- und Plan-Ressourcenbedarf werden regelmäßig miteinander verglichen • Zeitkritische Redaktionsaufgaben sind bekannt und dementsprechende Puffer werden berücksichtigt • Verbesserungspotenziale hinsichtlich des Redaktionsprozesses werden identifiziert | H21: Bitte auswählen | J21: • Klare Startpunkte erhöhen die Verlässlichkeit der Prozesse • Bessere Planbarkeit von Ressourcen und Terminen • Das Herunterbrechen in Einzelarbeitspakete erhöht die Transparenz im Redaktionsprozess und erleichtert die Identifikation von Verbesserungspotenzialen --> Verlässlichkeit und Effizienz | S21: =IF(H21="Nicht anwendbar","n.a.",0) -> 0 | T21: =IF(H21="Vollständig",1,0) -> 0 | U21: =IF(H21="In den meisten Fällen",0.75,0) -> 0 | V21: =IF(H21="In ein Paar Fällen",0.5,0) -> 0 | W21: =IF(H21="Gar nicht",0,0) -> 0 | X21: =IFERROR(SUM(T21:W26)/COUNTIF(H21:H26,"<>Nicht anwendbar"),"n.a.") -> 0 | Y21: =IF(Y17=1,X21,0) -> 0
C22: Finden regelmäßige Abstimmungen mit allen relevanten Stakeholdern statt? | H22: Bitte auswählen | S22: =IF(H22="Nicht anwendbar","n.a.",0) -> 0 | T22: =IF(H22="Vollständig",1,0) -> 0 | U22: =IF(H22="In den meisten Fällen",0.75,0) -> 0 | V22: =IF(H22="In ein Paar Fällen",0.5,0) -> 0 | W22: =IF(H22="Gar nicht",0,0) -> 0
C23: Wurde eine Ressourcenplanung für einzelne Aufgaben im Redaktionsprozess durchgeführt? | H23: Bitte auswählen | S23: =IF(H23="Nicht anwendbar","n.a.",0) -> 0 | T23: =IF(H23="Vollständig",1,0) -> 0 | U23: =IF(H23="In den meisten Fällen",0.75,0) -> 0 | V23: =IF(H23="In ein Paar Fällen",0.5,0) -> 0 | W23: =IF(H23="Gar nicht",0,0) -> 0
C24: Wird der reale Ressourcenbedarf dokumentiert und regelmäßig mit den Planungsdaten verglichen? | H24: Bitte auswählen | S24: =IF(H24="Nicht anwendbar","n.a.",0) -> 0 | T24: =IF(H24="Vollständig",1,0) -> 0 | U24: =IF(H24="In den meisten Fällen",0.75,0) -> 0 | V24: =IF(H24="In ein Paar Fällen",0.5,0) -> 0 | W24: =IF(H24="Gar nicht",0,0) -> 0
C25: Sind zeitkritische Redaktionsaufgaben bekannt und werden mit entsprechendem Puffer berücksichtigt? | H25: Bitte auswählen | S25: =IF(H25="Nicht anwendbar","n.a.",0) -> 0 | T25: =IF(H25="Vollständig",1,0) -> 0 | U25: =IF(H25="In den meisten Fällen",0.75,0) -> 0 | V25: =IF(H25="In ein Paar Fällen",0.5,0) -> 0 | W25: =IF(H25="Gar nicht",0,0) -> 0
C26: Werden Verbesserungspotentiale zur Vorgehensweise im Redaktionsprozess identifiziert? | H26: Bitte auswählen | S26: =IF(H26="Nicht anwendbar","n.a.",0) -> 0 | T26: =IF(H26="Vollständig",1,0) -> 0 | U26: =IF(H26="In den meisten Fällen",0.75,0) -> 0 | V26: =IF(H26="In ein Paar Fällen",0.5,0) -> 0 | W26: =IF(H26="Gar nicht",0,0) -> 0
B27: 4 | C27: Ist die Ressourcenplanung systemgestützt an den Entwicklungsprozess gekoppelt? | F27: • Die Ressourcenplanung ist systemgestützt an den Entwicklungsprozess gekoppelt • Die Performance-Daten aus dem Redaktionsprozess werden für Analysen weiter verwendet • Workflows wurden definiert • Aufgaben werden automatisiert mit Deadlines an die Verantwortlichen gesendet | H27: Bitte auswählen | J27: • Keine Verzögerung (durch die Redaktion) der Markteinführung • Verbesserte Zusammenarbeit zwischen Redaktion und Entwicklung • Transparenter Informationsfluss reduziert Medienbrüche und Fehler --> Zeit- und Qualitätsvorteile | S27: =IF(H27="Nicht anwendbar","n.a.",0) -> 0 | T27: =IF(H27="Vollständig",1,0) -> 0 | U27: =IF(H27="In den meisten Fällen",0.75,0) -> 0 | V27: =IF(H27="In ein Paar Fällen",0.5,0) -> 0 | W27: =IF(H27="Gar nicht",0,0) -> 0 | X27: =IFERROR(SUM(T27:W29)/COUNTIF(H27:H29,"<>Nicht anwendbar"),"n.a.") -> 0 | Y27: =IF(Y21=1,X27,0) -> 0
C28: Werden die Performance-Daten aus dem Redaktionsprozess weiter verwendet (z.B. zur verbesserten Prognose des Ressourcenbedarfs)? | H28: Bitte auswählen | S28: =IF(H28="Nicht anwendbar","n.a.",0) -> 0 | T28: =IF(H28="Vollständig",1,0) -> 0 | U28: =IF(H28="In den meisten Fällen",0.75,0) -> 0 | V28: =IF(H28="In ein Paar Fällen",0.5,0) -> 0 | W28: =IF(H28="Gar nicht",0,0) -> 0
C29: Wurden Workflows definiert? Werden die Aufgaben mit Deadlines an die Verantwortlichen gesendet (z.B. Ticketsystem)? | H29: Bitte auswählen | S29: =IF(H29="Nicht anwendbar","n.a.",0) -> 0 | T29: =IF(H29="Vollständig",1,0) -> 0 | U29: =IF(H29="In den meisten Fällen",0.75,0) -> 0 | V29: =IF(H29="In ein Paar Fällen",0.5,0) -> 0 | W29: =IF(H29="Gar nicht",0,0) -> 0
B30: 5 | C30: Wird bei Änderungen im Entwicklungsprozess (z.B. Produktänderungen) der Redaktionsprozess angestoßen? Werden die Ressourcen dynamisch angepasst? | F30: • Bei Änderungen im Entwicklungsprozess werden die tangierten Aufgaben im Redaktionsprozess angestoßen • Bei Änderungen im Entwicklungsprozess werden die Ressourcen dynamisch angepasst • Ressourcen werden automatisiert geplant und priorisiert • Basierend auf den aktuellen Entwicklungen werden Verbesserungspotenziale identifiziert, bewertet und umgesetzt | H30: Bitte auswählen | J30: • Dokumentation wird zu einem strategischen Enabler und unterstützt agile Entwicklungsprozesse und kann frühzeitig Wissen sichern • Automatische Initiierung senkt den manuellen Aufwand • Entlastung der Organisation durch vorausschauende Ressourcenplanung --> strategische Nutzung und Wettbewerbsvorteil | S30: =IF(H30="Nicht anwendbar","n.a.",0) -> 0 | T30: =IF(H30="Vollständig",1,0) -> 0 | U30: =IF(H30="In den meisten Fällen",0.75,0) -> 0 | V30: =IF(H30="In ein Paar Fällen",0.5,0) -> 0 | W30: =IF(H30="Gar nicht",0,0) -> 0 | X30: =IFERROR(SUM(T30:W32)/COUNTIF(H30:H32,"<>Nicht anwendbar"),"n.a.") -> 0 | Y30: =IF(Y27=1,X30,0) -> 0
C31: Werden benötigte Ressourcen für den Redaktionsprozess automatisiert geplant und priorisiert (z.B. auf Grundlage des Projektfortschritts)? | H31: Bitte auswählen | S31: =IF(H31="Nicht anwendbar","n.a.",0) -> 0 | T31: =IF(H31="Vollständig",1,0) -> 0 | U31: =IF(H31="In den meisten Fällen",0.75,0) -> 0 | V31: =IF(H31="In ein Paar Fällen",0.5,0) -> 0 | W31: =IF(H31="Gar nicht",0,0) -> 0
C32: Werden basierend auf aktuellen Entwicklungen Verbesserungspotentiale für den Redaktionsprozess identifiziert, bewertet und umgesetzt? | H32: Bitte auswählen | S32: =IF(H32="Nicht anwendbar","n.a.",0) -> 0 | T32: =IF(H32="Vollständig",1,0) -> 0 | U32: =IF(H32="In den meisten Fällen",0.75,0) -> 0 | V32: =IF(H32="In ein Paar Fällen",0.5,0) -> 0 | W32: =IF(H32="Gar nicht",0,0) -> 0

Sheet TD1.2
B4: Die Reifegrade werden anhand der jeweiligen Antwort ermittelt. Eine Erläuterung des Aufbaus der Reifegrade und der Antwortmöglichkeiten finden Sie in den Ausfüllhinweisen.
B6: TD1.2 | C6: Redaktionsprozess - Informationsbeschaffung | K6: Reifegrad: | L6: =ROUNDDOWN(Z16/0.25,0)*0.25 -> 0 | M6: =IF(L6<1,"Unvollständig",IF(L6<2,"Initial",IF(L6<3,"Gemanagt",IF(L6<4,"Definiert",IF(L6<5,"Quantitativ gemanagt",IF(L6<6,"Optimiert","Ausstehend")))))) -> Unvollständig
B7: Zweck | C7: Prozess zur Beschaffung der Informationen, die für den Redaktionsprozess erforderlich sind
B8: Ergebnisse | C8: • sämtliche Informationsquellen und Ansprechpartner sind bekannt und dokumentiert • Informationen erreichen die Redaktion automatisch im Push-Prinzip • Informationslücken sind erkannt, dokumentiert und mit Maßnahmen zur Schließung versehen
B9: Basispraktiken | C9: • Informationsbedarf definieren und dokumentieren • Geeignete Quellen identifizieren und dokumentieren • Informationsbeschaffung durchführen und dokumentieren
B10: Arbeitsprodukte | C10: • Quellenverzeichnis • Informationsanforderungsliste
B12: Erhebung der Reifegrade
B14: Zu Reifegrad | C14: Kontrollfrage | F14: Abnahmekriterien | H14: Umsetzung | J14: Nutzen bei Erreichen der Stufe | N14: Kommentar/Hinweis | T14: Listenindex | Y14: Zw. Ergebnis | Z14: Ergebnis
B16: 1 | C16: Wissen die Mitarbeiter, die mit der Technischen Dokumentation vertraut sind, aus der Erfahrung ungefähr, woher sie die erforderlichen Informationen bekommen bzw. sind die Informationsquellen zumindest grob definiert? | F16: • Mitarbeiter besitzen das Erfahrungswissen zur selbstständigen Beschaffung von Informationen | H16: Bitte auswählen | J16: / | S16: =IF(H16="Nicht anwendbar","n.a.",0) -> 0 | T16: =IF(H16="Vollständig",1,0) -> 0 | U16: =IF(H16="In den meisten Fällen",0.75,0) -> 0 | V16: =IF(H16="In ein Paar Fällen",0.5,0) -> 0 | W16: =IF(H16="Gar nicht",0,0) -> 0 | X16: =IF(S16>0,"n.a.",SUM(S16:W16)) -> 0 | Y16: =X16 -> 0 | Z16: =IF(Y16<>"n.a.",SUM(Y16,Y17,Y21,Y23,Y26),NA()) -> 0 | AG16: =IF(X16>0.5,"Umgesetzt","Nicht umgesetzt") -> Nicht umgesetzt
B17: 2 | C17: Ist identifiziert worden, welche Informationen im Redaktionsprozess für die technische Dokumentation erforderlich sind? | F17: • Die erforderlichen Informationen sind bekannt • Die Ansprechpartner für die erforderlichen Informationen bzw. die Informationsquellen sind bekannt • Die Ansprechpartner werden frühzeitig eingebunden • Es existiert eine Leitlinie für erforderliche Information und die zugehörigen Informationsquellen • Es sind Ziele und Vorgehensweisen für die Durchführung der Informationsbeschaffung festgelegt und dokumentiert | H17: Bitte auswählen | J17: • Reduzierte Abhängigkeit von Einzelpersonen • geringerer Zeitaufwand für wiederkehrende Informationsrecherchen • Verbesserung der Nachvollziehbarkeit durch vereinzelte Dokumentation von Quellen --> erste Stabilität und Entlastung | S17: =IF(H17="Nicht anwendbar","n.a.",0) -> 0 | T17: =IF(H17="Vollständig",1,0) -> 0 | U17: =IF(H17="In den meisten Fällen",0.75,0) -> 0 | V17: =IF(H17="In ein Paar Fällen",0.5,0) -> 0 | W17: =IF(H17="Gar nicht",0,0) -> 0 | X17: =IFERROR(SUM(T17:W20)/COUNTIF(H17:H20,"<>Nicht anwendbar"),"n.a.") -> 0 | Y17: =IF(X16=1,X17,0) -> 0 | AG17: =IF(X17>0.5,"Umgesetzt","Nicht umgesetzt") -> Nicht umgesetzt
C18: Sind die Ansprechpartner für die erforderlichen Informationen bzw. Informationsquellen bekannt und werden diese frühzeitig eingebunden? | H18: Bitte auswählen | S18: =IF(H18="Nicht anwendbar","n.a.",0) -> 0 | T18: =IF(H18="Vollständig",1,0) -> 0 | U18: =IF(H18="In den meisten Fällen",0.75,0) -> 0 | V18: =IF(H18="In ein Paar Fällen",0.5,0) -> 0 | W18: =IF(H18="Gar nicht",0,0) -> 0 | AG18: =IF(X18>0.5,"Umgesetzt","Nicht umgesetzt") -> Nicht umgesetzt
C19: Existiert eine Leitlinie für erforderliche Information und die zugehörigen Informationsquellen und wird diese gelegentlich aktualisiert? | H19: Bitte auswählen | S19: =IF(H19="Nicht anwendbar","n.a.",0) -> 0 | T19: =IF(H19="Vollständig",1,0) -> 0 | U19: =IF(H19="In den meisten Fällen",0.75,0) -> 0 | V19: =IF(H19="In ein Paar Fällen",0.5,0) -> 0 | W19: =IF(H19="Gar nicht",0,0) -> 0 | AG19: =IF(X19>0.5,"Umgesetzt","Nicht umgesetzt") -> Nicht umgesetzt
C20: Sind Ziele und Vorgehensweisen für die Durchführung der Informationsbeschaffung festgelegt und dokumentiert? | H20: Bitte auswählen | S20: =IF(H20="Nicht anwendbar","n.a.",0) -> 0 | T20: =IF(H20="Vollständig",1,0) -> 0 | U20: =IF(H20="In den meisten Fällen",0.75,0) -> 0 | V20: =IF(H20="In ein Paar Fällen",0.5,0) -> 0 | W20: =IF(H20="Gar nicht",0,0) -> 0 | AG20: =IF(X20>0.5,"Umgesetzt","Nicht umgesetzt") -> Nicht umgesetzt
B21: 3 | C21: Erfolgt die Informationsbeschaffung regelmäßig im Push-Prinzip von den Abteilungen zur Redaktion (z.B. von einzelnen Abteilungen / für einzelne Informationen)? | F21: • Der Informationsfluss erfolgt regelmäßig im Push-Prinzip • Es ist ein systematischer Informationsbeschaffungsprozess mit Rollen und Verantwortlichkeiten definiert | H21: Bitte auswählen | J21: • Die Etablierung des Push-Prinzips sorgt für erhöhte Transaprenz und Nachvollziehbarkeit über Informationsflüsse • verlässliche Infpormationsqualität und -vollständigkeit • effizientere Redaktionsarbeit durch weniger Doppelarbeit und Korrekturschleifen --> verlässliche Prozesse und Qualität | S21: =IF(H21="Nicht anwendbar","n.a.",0) -> 0 | T21: =IF(H21="Vollständig",1,0) -> 0 | U21: =IF(H21="In den meisten Fällen",0.75,0) -> 0 | V21: =IF(H21="In ein Paar Fällen",0.5,0) -> 0 | W21: =IF(H21="Gar nicht",0,0) -> 0 | X21: =IFERROR(SUM(T21:W22)/COUNTIF(H21:H22,"<>Nicht anwendbar"),"n.a.") -> 0 | Y21: =IF(Y17=1,X21,0) -> 0
C22: Ist ein systematischer Informationsbeschaffungsprozess mit Rollen und Verantwortlichkeiten definiert? | H22: Bitte auswählen | S22: =IF(H22="Nicht anwendbar","n.a.",0) -> 0 | T22: =IF(H22="Vollständig",1,0) -> 0 | U22: =IF(H22="In den meisten Fällen",0.75,0) -> 0 | V22: =IF(H22="In ein Paar Fällen",0.5,0) -> 0 | W22: =IF(H22="Gar nicht",0,0) -> 0
B23: 4 | C23: Gelangen alle erforderliche Informationen im Push-Prinzip zur Redaktion? | F23: • Die Informationen erreichen die Redaktion im Push-Prinzip • Redundanzen in den Informationen werden vermieden • Der Informationsfluss ist ganzheitlich modelliert und definiert • Der Informationsfluss wird regelmäßig überprüft • Die Redaktion stützt sich bei der Informationsbeschaffung auf eine Single Source of Truth | H23: Bitte auswählen | J23: • reduzierte Fehleranfälligkeit durch Wegfall von manuellen Übergaben • Bessere Abstimmung mit anderen Abteilungen - redundante Arbeiten werden abteilungsübergreifend reduziert • erhöhte Termintreue, da benötigte Informationen planbar verfügbar sind --> Integration bringt Effizienz und Konsistenz | S23: =IF(H23="Nicht anwendbar","n.a.",0) -> 0 | T23: =IF(H23="Vollständig",1,0) -> 0 | U23: =IF(H23="In den meisten Fällen",0.75,0) -> 0 | V23: =IF(H23="In ein Paar Fällen",0.5,0) -> 0 | W23: =IF(H23="Gar nicht",0,0) -> 0 | X23: =IFERROR(SUM(T23:W25)/COUNTIF(H23:H25,"<>Nicht anwendbar"),"n.a.") -> 0 | Y23: =IF(Y21=1,X23,0) -> 0
C24: Ist ein ganzheitlicher Informationsfluss modelliert und definiert? Wird dieser regelmäßig überprüft? | H24: Bitte auswählen | S24: =IF(H24="Nicht anwendbar","n.a.",0) -> 0 | T24: =IF(H24="Vollständig",1,0) -> 0 | U24: =IF(H24="In den meisten Fällen",0.75,0) -> 0 | V24: =IF(H24="In ein Paar Fällen",0.5,0) -> 0 | W24: =IF(H24="Gar nicht",0,0) -> 0
C25: Werden Redundanzen vermieden und kann sich die Redaktion auf eine Single Source of Truth verlassen? | H25: Bitte auswählen | S25: =IF(H25="Nicht anwendbar","n.a.",0) -> 0 | T25: =IF(H25="Vollständig",1,0) -> 0 | U25: =IF(H25="In den meisten Fällen",0.75,0) -> 0 | V25: =IF(H25="In ein Paar Fällen",0.5,0) -> 0 | W25: =IF(H25="Gar nicht",0,0) -> 0
B26: 5 | C26: Gelangen die Informationen automatisiert und normalisiert zur Redaktion? | F26: • Die Informationen gelangen automatisiert und normalisiert zur Redaktion • Der Informationsbeschaffungsprozess wird kontinuierlich verbessert • Es werden basierend auf den aktuellen Entwicklungen Verbesserungspotenziale für die Informationsbeschaffung identifiziert, bewertet und umgesetzt | H26: Bitte auswählen | J26: • Effizienzgewinne durch Wegfall von Such- und Abstimmungsaufwänden • kontiunierliche Aktualität der Informationen Wettbewerbsvorteil durch höhere Geschwindigkeiten bei Markteinführungen und Änderungsumsetzungen --> Proaktivität und Automatisierung sichern strategische Vorteile | S26: =IF(H26="Nicht anwendbar","n.a.",0) -> 0 | T26: =IF(H26="Vollständig",1,0) -> 0 | U26: =IF(H26="In den meisten Fällen",0.75,0) -> 0 | V26: =IF(H26="In ein Paar Fällen",0.5,0) -> 0 | W26: =IF(H26="Gar nicht",0,0) -> 0 | X26: =IFERROR(SUM(T26:W28)/COUNTIF(H26:H28,"<>Nicht anwendbar"),"n.a.") -> 0 | Y26: =IF(Y23=1,X26,0) -> 0
C27: Wird der Prozess der Informationsbeschaffung kontinuierlich verbessert? | H27: Bitte auswählen | S27: =IF(H27="Nicht anwendbar","n.a.",0) -> 0 | T27: =IF(H27="Vollständig",1,0) -> 0 | U27: =IF(H27="In den meisten Fällen",0.75,0) -> 0 | V27: =IF(H27="In ein Paar Fällen",0.5,0) -> 0 | W27: =IF(H27="Gar nicht",0,0) -> 0
C28: Werden basierend auf aktuellen Entwicklungen Verbesserungspotentiale für die Informationsbeschaffung identifiziert, bewertet und umgesetzt? | H28: Bitte auswählen | S28: =IF(H28="Nicht anwendbar","n.a.",0) -> 0 | T28: =IF(H28="Vollständig",1,0) -> 0 | U28: =IF(H28="In den meisten Fällen",0.75,0) -> 0 | V28: =IF(H28="In ein Paar Fällen",0.5,0) -> 0 | W28: =IF(H28="Gar nicht",0,0) -> 0

Sheet TD1.3
B4: Die Reifegrade werden anhand der jeweiligen Antwort ermittelt. Eine Erläuterung des Aufbaus der Reifegrade und der Antwortmöglichkeiten finden Sie in den Ausfüllhinweisen.
B6: TD1.3 | C6: Redaktionsprozess - Interne Zusammenarbeit | K6: Reifegrad: | L6: =ROUNDDOWN(Z16/0.25,0)*0.25 -> 0 | M6: =IF(L6<1,"Unvollständig",IF(L6<2,"Initial",IF(L6<3,"Gemanagt",IF(L6<4,"Definiert",IF(L6<5,"Quantitativ gemanagt",IF(L6<6,"Optimiert","Ausstehend")))))) -> Unvollständig
B7: Zweck | C7: Zusammenarbeit zwischen den Mitarbeitern, die an der technischen Dokumentation arbeiten bzw. dafür verantwortlich sind untereinander sowie mit anderen, tangierten Abteilungen
B8: Ergebnisse | C8: • Kollaborative Zusammenarbeit abteilungsintern • Kollaborative Zusammenarbeit abteilungsübergreifend • Abteilungsübergreifende Teamkultur • Ganzheitliche Sicht auf Redaktionsprozesse und Entwicklungsprozesse
B9: Basispraktiken | C9: • regelmäßige Abstimmungen innerhalb der Redaktion und abteilungsübergreifend • Förderung einer kollaborativen Unternehmenskultur durch Schulungen oder Guidelines • Nutzung gemeinsamer Tools und Plattformen zur Koordination und Dokumentation
B10: Arbeitsprodukte | C10: • Regeln und Praktiken zur Zusammenarbeit • Rollen- und Verantwortlichkeitsmatrix • gemeinsame Informationsplattformen oder Tools
B12: Erhebung der Reifegrade
B14: Zu Reifegrad | C14: Kontrollfrage | F14: Abnahmekriterien | H14: Umsetzung | J14: Nutzen bei Erreichen der Stufe | N14: Kommentar/Hinweis | T14: Listenindex | Y14: Zw. Ergebnis | Z14: Ergebnis
B16: 1 | C16: Wird bei Bedarf projektbezogenen mit anderen Redakteuren bzw. für die Dokumentation verantwortlichen Personen zusammengearbeitet? | F16: • Bei Bedarf wird projektbezogen mit anderen Redakteuren bzw. für die Dokumentation verantwortlichen Personen zusammengearbeitet | H16: Bitte auswählen | J16: / | S16: =IF(H16="Nicht anwendbar","n.a.",0) -> 0 | T16: =IF(H16="Vollständig",1,0) -> 0 | U16: =IF(H16="In den meisten Fällen",0.75,0) -> 0 | V16: =IF(H16="In ein Paar Fällen",0.5,0) -> 0 | W16: =IF(H16="Gar nicht",0,0) -> 0 | X16: =IF(S16>0,"n.a.",SUM(S16:W16)) -> 0 | Y16: =X16 -> 0 | Z16: =IF(Y16<>"n.a.",SUM(Y16,Y17,Y21,Y25,Y29),NA()) -> 0 | AG16: =IF(X16>0.5,"Umgesetzt","Nicht umgesetzt") -> Nicht umgesetzt
B17: 2 | C17: Wird gelegentlich mit anderen Redakteuren zum Zweck des Informations- und Erfahrungsaustausch zusammengearbeitet? | F17: • Es wird gelegentlich mit anderen Redakteuren zum Zweck des Informations- und Erfahrungsaustausch zusammengearbeitet • Durch eine Zusammenarbeit wird doppelte Arbeit durch mehrere Personen innerhalb der Redaktion vermieden • Verantwortlichkeiten in der Redaktion sind projektbezogen definiert und dokumentiert • Informationen bzw. Inhalte werden gelegentlich mit anderen Mitarbeitern innerhalb der Redaktion geteilt | H17: Bitte auswählen | J17: • Verbesserung der Transparenz durch vereinzelte Kommunikationsroutinen • Reduzierte Abhängigkeit von Einzelpersonen • Erste Entlastung durch definierte Ansprechpersonen oder Absprachen --> erste Transparenz und Entlastung | S17: =IF(H17="Nicht anwendbar","n.a.",0) -> 0 | T17: =IF(H17="Vollständig",1,0) -> 0 | U17: =IF(H17="In den meisten Fällen",0.75,0) -> 0 | V17: =IF(H17="In ein Paar Fällen",0.5,0) -> 0 | W17: =IF(H17="Gar nicht",0,0) -> 0 | X17: =IFERROR(SUM(T17:W20)/COUNTIF(H17:H20,"<>Nicht anwendbar"),"n.a.") -> 0 | Y17: =IF(X16=1,X17,0) -> 0 | AG17: =IF(X17>0.5,"Umgesetzt","Nicht umgesetzt") -> Nicht umgesetzt
C18: Wird durch eine Zusammenarbeit doppelte Arbeit durch mehrere Personen innerhalb der Redaktion gelegentlich vermieden? | H18: Bitte auswählen | S18: =IF(H18="Nicht anwendbar","n.a.",0) -> 0 | T18: =IF(H18="Vollständig",1,0) -> 0 | U18: =IF(H18="In den meisten Fällen",0.75,0) -> 0 | V18: =IF(H18="In ein Paar Fällen",0.5,0) -> 0 | W18: =IF(H18="Gar nicht",0,0) -> 0 | AG18: =IF(X18>0.5,"Umgesetzt","Nicht umgesetzt") -> Nicht umgesetzt
C19: Sind Verantwortlichkeiten in der Redaktion projektbezogen definiert und dokumentiert? | H19: Bitte auswählen | S19: =IF(H19="Nicht anwendbar","n.a.",0) -> 0 | T19: =IF(H19="Vollständig",1,0) -> 0 | U19: =IF(H19="In den meisten Fällen",0.75,0) -> 0 | V19: =IF(H19="In ein Paar Fällen",0.5,0) -> 0 | W19: =IF(H19="Gar nicht",0,0) -> 0 | AG19: =IF(X19>0.5,"Umgesetzt","Nicht umgesetzt") -> Nicht umgesetzt
C20: Werden Informationen bzw. Inhalte gelegentlich mit anderen Mitarbeitern innerhalb der Redaktion geteilt? | H20: Bitte auswählen | S20: =IF(H20="Nicht anwendbar","n.a.",0) -> 0 | T20: =IF(H20="Vollständig",1,0) -> 0 | U20: =IF(H20="In den meisten Fällen",0.75,0) -> 0 | V20: =IF(H20="In ein Paar Fällen",0.5,0) -> 0 | W20: =IF(H20="Gar nicht",0,0) -> 0 | AG20: =IF(X20>0.5,"Umgesetzt","Nicht umgesetzt") -> Nicht umgesetzt
B21: 3 | C21: Existiert ein definierter Prozess zur projektbegleitenden, abteilungsübergreifenden Zusammenarbeit? | F21: • Es existiert ein definierter Prozess zur projektbegleitenden, abteilungsübergreifenden Zusammenarbeit • Es werden regelmäßig abteilungsübergreifend Teams zur Zusammenarbeit gebildet • Die Mitarbeiter sind sensibilisiert für die Informationsergebnisse anderer Abteilungen, wodurch doppelte Arbeit abteilungsübergreifend vermieden werden kann • Innerhalb der Teams werden Entscheidungen für den Entwicklungs- und den Redaktionsprozess getroffen | H21: Bitte auswählen | J21: • verbesserte Planbarkeit von Arbeitsaufwänden über Abteilungsgrenzen hinweg • Fehlerreduktion durch nachvollziehbare Zuständigkeiten • Redundanzreduktion durch abteilungsübergreifenden Austausch --> Effizienz und Verlässlichkeit | S21: =IF(H21="Nicht anwendbar","n.a.",0) -> 0 | T21: =IF(H21="Vollständig",1,0) -> 0 | U21: =IF(H21="In den meisten Fällen",0.75,0) -> 0 | V21: =IF(H21="In ein Paar Fällen",0.5,0) -> 0 | W21: =IF(H21="Gar nicht",0,0) -> 0 | X21: =IFERROR(SUM(T21:W24)/COUNTIF(H21:H24,"<>Nicht anwendbar"),"n.a.") -> 0 | Y21: =IF(Y17=1,X21,0) -> 0
C22: Werden regelmäßig abteilungsübergreifend Teams zur Zusammenarbeit gebildet? | H22: Bitte auswählen | S22: =IF(H22="Nicht anwendbar","n.a.",0) -> 0 | T22: =IF(H22="Vollständig",1,0) -> 0 | U22: =IF(H22="In den meisten Fällen",0.75,0) -> 0 | V22: =IF(H22="In ein Paar Fällen",0.5,0) -> 0 | W22: =IF(H22="Gar nicht",0,0) -> 0
C23: Sind die Mitarbeiter sensibilisiert für die Informationsergebnisse anderer Abteilungen, wodurch doppelte Arbeit abteilungsübergreifend vermieden werden kann? | H23: Bitte auswählen | S23: =IF(H23="Nicht anwendbar","n.a.",0) -> 0 | T23: =IF(H23="Vollständig",1,0) -> 0 | U23: =IF(H23="In den meisten Fällen",0.75,0) -> 0 | V23: =IF(H23="In ein Paar Fällen",0.5,0) -> 0 | W23: =IF(H23="Gar nicht",0,0) -> 0
C24: Werden innerhalb der Teams Entscheidungen für den Entwicklungs- und den Redaktionsprozess getroffen? | H24: Bitte auswählen | S24: =IF(H24="Nicht anwendbar","n.a.",0) -> 0 | T24: =IF(H24="Vollständig",1,0) -> 0 | U24: =IF(H24="In den meisten Fällen",0.75,0) -> 0 | V24: =IF(H24="In ein Paar Fällen",0.5,0) -> 0 | W24: =IF(H24="Gar nicht",0,0) -> 0
B25: 4 | C25: Sind innerhalb der Teams Rollen definiert und werden diese regelmäßig überprüft? | F25: • Innerhalb der Teams sind Rollen definiert und werden diese regelmäßig überprüft • Die crossfunktionale Teamarbeit wird mit Hilfe von Kennzahlen gesteuert • Innerhalb der Teams herrscht die Überzeugung, dass gemeinsam bessere Ergebnisse erreicht werden als allein • Die Teamarbeit wird mithilfe von Tools unterstützt | H25: Bitte auswählen | J25: • deutllich verbesserter Wissensaustausch • stärkere Einbindung verschiedener Abteilungen führt zu weniger Medienbrüchen • gesteigerte Mitarbeiterzufriedenheit durch klare Kommunikationswege --> Integration bringt Geschwindigkeit, bessere Qualität und höherre Zufriedenheit | S25: =IF(H25="Nicht anwendbar","n.a.",0) -> 0 | T25: =IF(H25="Vollständig",1,0) -> 0 | U25: =IF(H25="In den meisten Fällen",0.75,0) -> 0 | V25: =IF(H25="In ein Paar Fällen",0.5,0) -> 0 | W25: =IF(H25="Gar nicht",0,0) -> 0 | X25: =IFERROR(SUM(T25:W28)/COUNTIF(H25:H28,"<>Nicht anwendbar"),"n.a.") -> 0 | Y25: =IF(Y21=1,X25,0) -> 0
C26: Wird die crossfunktionale Teamarbeit mit Hilfe von Kennzahlen gesteuert? | H26: Bitte auswählen | S26: =IF(H26="Nicht anwendbar","n.a.",0) -> 0 | T26: =IF(H26="Vollständig",1,0) -> 0 | U26: =IF(H26="In den meisten Fällen",0.75,0) -> 0 | V26: =IF(H26="In ein Paar Fällen",0.5,0) -> 0 | W26: =IF(H26="Gar nicht",0,0) -> 0
C27: Herrscht innerhalb der Teams die Überzeugung, dass gemeinsam bessere Ergebnisse erreicht werden als allein? | H27: Bitte auswählen | S27: =IF(H27="Nicht anwendbar","n.a.",0) -> 0 | T27: =IF(H27="Vollständig",1,0) -> 0 | U27: =IF(H27="In den meisten Fällen",0.75,0) -> 0 | V27: =IF(H27="In ein Paar Fällen",0.5,0) -> 0 | W27: =IF(H27="Gar nicht",0,0) -> 0
C28: Wird die Teamarbeit mithilfe von Tools unterstützt? | H28: Bitte auswählen | S28: =IF(H28="Nicht anwendbar","n.a.",0) -> 0 | T28: =IF(H28="Vollständig",1,0) -> 0 | U28: =IF(H28="In den meisten Fällen",0.75,0) -> 0 | V28: =IF(H28="In ein Paar Fällen",0.5,0) -> 0 | W28: =IF(H28="Gar nicht",0,0) -> 0
B29: 5 | C29: Wird die Zusammenarbeit und Kommunikation im Team kontinuierlich verbessert? | F29: • Die Zusammenarbeit und Kommunikation im Team wird kontinuierlich verbessert • Es werden kontinuierlich neue Möglichkeiten der Zusammenarbeit identifiziert, bewertet und umgesetzt | H29: Bitte auswählen | J29: • nachhaltige Effizienzsteigerung durch kontinuierliche Verbesserung • Organisation entwickelt eine Kultur des Wissensaustauschs und der Transparenz • hohe Innovationsfähigkeit durch crossfunktionale, nahtlose Zusammenarbeit --> Optimierung sichert Innovationskraft und eine kollaborative Unternehmenskultur | S29: =IF(H29="Nicht anwendbar","n.a.",0) -> 0 | T29: =IF(H29="Vollständig",1,0) -> 0 | U29: =IF(H29="In den meisten Fällen",0.75,0) -> 0 | V29: =IF(H29="In ein Paar Fällen",0.5,0) -> 0 | W29: =IF(H29="Gar nicht",0,0) -> 0 | X29: =IFERROR(SUM(T3:W29)/COUNTIF(H29:H30,"<>Nicht anwendbar"),"n.a.") -> 0 | Y29: =IF(Y25=1,X29,0) -> 0
C30: Werden kontinuierlich neue Möglichkeiten der Zusammenarbeit identifiziert, bewertet und umgesetzt? | H30: Bitte auswählen | S30: =IF(H30="Nicht anwendbar","n.a.",0) -> 0 | T30: =IF(H30="Vollständig",1,0) -> 0 | U30: =IF(H30="In den meisten Fällen",0.75,0) -> 0 | V30: =IF(H30="In ein Paar Fällen",0.5,0) -> 0 | W30: =IF(H30="Gar nicht",0,0) -> 0

Sheet TD1.4
B4: Die Reifegrade werden anhand der jeweiligen Antwort ermittelt. Eine Erläuterung des Aufbaus der Reifegrade und der Antwortmöglichkeiten finden Sie in den Ausfüllhinweisen.
B6: TD1.4 | C6: Redaktionsprozess - Externe Zusammenarbeit | K6: Reifegrad: | L6: =ROUNDDOWN(Z16/0.25,0)*0.25 -> 0 | M6: =IF(L6<1,"Unvollständig",IF(L6<2,"Initial",IF(L6<3,"Gemanagt",IF(L6<4,"Definiert",IF(L6<5,"Quantitativ gemanagt",IF(L6<6,"Optimiert","Ausstehend")))))) -> Unvollständig
B7: Zweck | C7: Die Zusammenarbeit der Redaktion mit externen Partnern außerhalb der Organisation. Dies können etwa Dienstleister für die technische Dokumentation sein (z.B. Übersetzungsdienstleister) oder Partner innerhalb des Entwicklungsprozesses (z.B. Lieferanten)
B8: Ergebnisse | C8: • Relevante externe Partner sind identifiziert, eingebunden und ihre Rollen definiert • Kommunikations- und Abstimmungswege mit externen Akteuren sind definiert • Vereinbarungen sind dokumentiert • Externe Beiträge sind integriert und konsistent mit der Gesamtdokumentation
B9: Basispraktiken | C9: • Klare Definition von Schnittstellen, Verantwortlichkeiten und Qualitätskriterien • Regelmäßige Abstimmungsrunden oder Statusmeetings mit externen Partnern • Nutzung von Tools und Plattformen
B10: Arbeitsprodukte | C10: • Verträge, Vereinbarungen oder Service Level Agreements (SLA) mit externen Partnern • Dokumentierte Kommunikations- und Schnittstellenregeln für externe Zusammenarbeit • Gemeinsame Arbeitsplattformen oder Austauschformate
B12: Erhebung der Reifegrade
B14: Zu Reifegrad | C14: Kontrollfrage | F14: Abnahmekriterien | H14: Umsetzung | J14: Nutzen bei Erreichen der Stufe | N14: Kommentar/Hinweis | T14: Listenindex | Y14: Zw. Ergebnis | Z14: Ergebnis
B16: 1 | C16: Kann die externe Kommunikation situativ über Dritte (z. B. Projektleitung) erfolgen, wenn dies erforderlich ist? | F16: • Die Kommunikation erfolgt über Dritte (z.B. Projektleiter) | H16: Bitte auswählen | J16: / | S16: =IF(H16="Nicht anwendbar","n.a.",0) -> 0 | T16: =IF(H16="Vollständig",1,0) -> 0 | U16: =IF(H16="In den meisten Fällen",0.75,0) -> 0 | V16: =IF(H16="In ein Paar Fällen",0.5,0) -> 0 | W16: =IF(H16="Gar nicht",0,0) -> 0 | X16: =IF(S16>0,"n.a.",SUM(S16:W16)) -> 0 | Y16: =X16 -> 0 | Z16: =IF(Y16<>"n.a.",SUM(Y16,Y17,Y20,Y23,Y27),NA()) -> 0
B17: 2 | C17: Gibt es definierte Ansprechpartner bei externen Partnern für die Redaktion und sind diese dokumentiert? | F17: • Es gibt definierte Ansprechpartner bei externen Partnern für die Redaktion • Die externe Zusammenarbeit erfolgt gelegentlich projektbezogen • Absprachen mit externen Partnern werden gelegentlich dokumentiert | H17: Bitte auswählen | J17: • Aufbau von Verlässlichkeit in bestimmten Kooperationen • Verringerte Such- und Abstimmungsaufwände durch bekannte Ansprechpartner --> erste Stabilität durch feste Partner | S17: =IF(H17="Nicht anwendbar","n.a.",0) -> 0 | T17: =IF(H17="Vollständig",1,0) -> 0 | U17: =IF(H17="In den meisten Fällen",0.75,0) -> 0 | V17: =IF(H17="In ein Paar Fällen",0.5,0) -> 0 | W17: =IF(H17="Gar nicht",0,0) -> 0 | X17: =IFERROR(SUM(T17:W19)/COUNTIF(H17:H19,"<>Nicht anwendbar"),"n.a.") -> 0 | Y17: =IF(X16=1,X17,0) -> 0 | AG17: =IF(X18>0.5,"Umgesetzt","Nicht umgesetzt") -> Nicht umgesetzt
C18: Erfolgt die externe Zusammenarbeit projektbezogen gelegentlich zwischen externen Partnern und der Redaktion? | H18: Bitte auswählen | S18: =IF(H18="Nicht anwendbar","n.a.",0) -> 0 | T18: =IF(H18="Vollständig",1,0) -> 0 | U18: =IF(H18="In den meisten Fällen",0.75,0) -> 0 | V18: =IF(H18="In ein Paar Fällen",0.5,0) -> 0 | W18: =IF(H18="Gar nicht",0,0) -> 0 | AG18: =IF(X19>0.5,"Umgesetzt","Nicht umgesetzt") -> Nicht umgesetzt
C19: Werden Absprachen mit externen Partnern gelegentlich dokumentiert? | H19: Bitte auswählen | S19: =IF(H19="Nicht anwendbar","n.a.",0) -> 0 | T19: =IF(H19="Vollständig",1,0) -> 0 | U19: =IF(H19="In den meisten Fällen",0.75,0) -> 0 | V19: =IF(H19="In ein Paar Fällen",0.5,0) -> 0 | W19: =IF(H19="Gar nicht",0,0) -> 0 | AG19: =IF(#REF!>0.5,"Umgesetzt","Nicht umgesetzt") -> #REF!
B20: 3 | C20: Ist die Zusammenarbeit der Redaktion mit externen Partnern vertraglich geregelt? | F20: • Die Zusammenarbeit mit externen Partnern ist vertraglich geregelt • Es gibt standardisierte Schnittstellen und Übergabeformate zu den Partnern für den Informationsaustausch und für die Integration externer Inhalte in die technische Dokumentation • Rollen, Verantwortlichkeiten und Kommunikationswege mit externen Partnern sind klar festgelegt und dokumentiert | H20: Bitte auswählen | J20: • höhere Qualität und Konsistenz externer Leistungen • geringeres Risiko durch klar geregelte Abläufe und Verträge • verbesserte Nachvollziehbarkeit und Dokumentation der Zusammenarbeit --> Qualität und Planbarkeit steigen | S20: =IF(H20="Nicht anwendbar","n.a.",0) -> 0 | T20: =IF(H20="Vollständig",1,0) -> 0 | U20: =IF(H20="In den meisten Fällen",0.75,0) -> 0 | V20: =IF(H20="In ein Paar Fällen",0.5,0) -> 0 | W20: =IF(H20="Gar nicht",0,0) -> 0 | X20: =IFERROR(SUM(T20:W22)/COUNTIF(H20:H22,"<>Nicht anwendbar"),"n.a.") -> 0 | Y20: =IF(Y17=1,X20,0) -> 0
C21: Gibt es standardisierte Schnittstellen und Übergabeformate zu den Partnern für den Informationsaustausch und für die Integration externer Inhalte in die technische Dokumentation? | H21: Bitte auswählen | S21: =IF(H21="Nicht anwendbar","n.a.",0) -> 0 | T21: =IF(H21="Vollständig",1,0) -> 0 | U21: =IF(H21="In den meisten Fällen",0.75,0) -> 0 | V21: =IF(H21="In ein Paar Fällen",0.5,0) -> 0 | W21: =IF(H21="Gar nicht",0,0) -> 0
C22: Sind Rollen, Verantwortlichkeiten und Kommunikationswege mit externen Partnern definiert und dokumentiert? | H22: Bitte auswählen | S22: =IF(H22="Nicht anwendbar","n.a.",0) -> 0 | T22: =IF(H22="Vollständig",1,0) -> 0 | U22: =IF(H22="In den meisten Fällen",0.75,0) -> 0 | V22: =IF(H22="In ein Paar Fällen",0.5,0) -> 0 | W22: =IF(H22="Gar nicht",0,0) -> 0
B23: 4 | C23: Werden in der externen Zusammenarbeit der Redaktion gemeinsame Tools verwendet? | F23: • In der externen Zusammenarbeit werden gemeinsame Tools verwendet • In der externen Zusammenarbeit werden gemeinsame (Qualitäts-) Ziele verfolgt • Die Leistungen werden anhand gemeinsam definierter KPIs regelmäßig überprüft und gesteuert • Die externe Zusammenarbeit wird auf der Grundlage gemeinsamer Workflows durchgeführt | H23: Bitte auswählen | J23: • beschleunigte Prozesse durch digitale Integration externer Partner • weniger Medienbrüche • nahtlose Abstimmung und Qualitätskontrolle engere Bindung und langfristige Partnerschaften mit externen Akteuren --> Integration bringt Effizienz und Geschwindigkeit | S23: =IF(H23="Nicht anwendbar","n.a.",0) -> 0 | T23: =IF(H23="Vollständig",1,0) -> 0 | U23: =IF(H23="In den meisten Fällen",0.75,0) -> 0 | V23: =IF(H23="In ein Paar Fällen",0.5,0) -> 0 | W23: =IF(H23="Gar nicht",0,0) -> 0 | X23: =IFERROR(SUM(T23:W26)/COUNTIF(H23:H26,"<>Nicht anwendbar"),"n.a.") -> 0 | Y23: =IF(Y20=1,X23,0) -> 0
